Workbook

Sheet Dictionary
A1: Bank_ID | B1: Name | C1: Name_EBA | D1: ISO2 | E1: Country_Label
A2: AT001 | B2: BAWAG | C2: BAWAG Group AG | D2: AT | E2: Austria
A3: AT002 | B3: Erste Group | C3: Erste Group Bank AG | D3: AT | E3: Austria
A4: AT003 | B4: Österreichische Volksbanken-Aktiengesellschaft | C4: Österreichische Volksbanken-AG with credit institutions affiliated according to Article 10 of the CR | D4: AT | E4: Austria
A5: AT004 | B5: Promontoria Sacher Holding | C5: Promontoria Sacher Holding N.V. | D5: AT | E5: Austria
A6: AT005 | B6: Raiffeisen Bank International | C6: Raiffeisen Bank International AG | D6: AT | E6: Austria
A7: AT006 | B7: Raiffeisen Zentralbank Österreich | C7: Raiffeisen Zentralbank Österreich AG | D7: AT | E7: Austria
A8: AT007 | B8: Raiffeisen Bankengruppe OÖ | C8: Raiffeisenbankengruppe OÖ Verbund eGen | D8: AT | E8: Austria
A9: AT008 | B9: Raiffeisen-Holding NÖ-Wien | C9: Raiffeisen-Holding Niederösterreich-Wien | D9: AT | E9: Austria
A10: AT009 | B10: Raiffeisenlandesbank Oberösterreich | C10: Raiffeisenlandesbank Oberösterreich AG | D10: AT | E10: Austria
A11: AT010 | B11: Raiffeisen-Landesbanken-Holding | C11: Raiffeisen-Landesbanken-Holding GmbH | D11: AT | E11: Austria
A12: AT011 | B12: Sberbank Europe Group | C12: Sberbank Europe AG | D12: AT | E12: Austria
... A234: XX001 | B234: All Other Banks | C234: All other banks | D234: XX | E234: Other

Sheet ST
A1: Value_Scenario | B1: Label_Scenario | C1: Value_Country | D1: Label_Country | E1: ISO2_Country | F1: Value_Portfolio | G1: Label_Portfolio | H1: Value_Maturity | I1: Label_Maturity | J1: Value_Exposure | K1: Label_Exposure | L1: Value_Status | M1: Label_Status | N1: Value_Perf_Status | O1: Label_Perf_Status | P1: Value_IFRS9_Stages | Q1: Label_IFRS9_Stages | R1: Value_CR_Guarantees | S1: Label_CR_Guarantees | T1: Value_CR_exp_moratoria | U1: Label_CR_exp_moratoria | V1: Value_Perf_Forborne | W1: Label_Perf_Forborne | X1: Value_Fact_Chart | Y1: Label_Fact_Chart | Z1: Bank_ID | AA1: Name | AB1: Name_EBA | AC1: Bank_ISO2 | AD1: ISO2 | AE1: Country
A2: 0 | B2: No breakdown | C2: 0 | D2: Total / No Breakdown | E2: TOT | F2: 0 | G2: Total / No breakdown by portfolio | H2: 0 | I2: No breakdown by maturity | J2: 0 | K2: TOTAL | L2: 0 | M2: No breakdown by status | N2: 0 | O2: No breakdown by Perf_status | P2: 0 | Q2: No breakdown by IFRS9_Stages | R2: 0 | S2: No breakdown | T2: 0 | U2: No breakdown | V2: 0 | W2: Total / No Breakdown | X2: 0 | Y2: NA | Z2: AT001 | AA2: BAWAG | AB2: BAWAG Group AG | AC2: AT | AD2: AT | AE2: Austria
A3: 1 | B3: Actual | C3: 1 | D3: Austria | E3: AT | F3: 1 | G3: SA | H3: 1 | I3: [ 0 - 3M ] | J3: 1000 | K3: Total excl. Sovereign (2011) | L3: 1 | M3: Non defaulted assets | N3: 1 | O3: Performing | P3: 1 | Q3: Stage 1 | R3: 1 | S3: Guaranteed | T3: 1 | U3: Expired | V3: 1 | W3: Debt Instruments - other than HFT | X3: 1 | Y3: No | Z3: AT002 | AA3: Erste Group | AB3: Erste Group Bank AG | AC3: AT | AD3: BE | AE3: Belgium
A4: 11 | B4: Actual restated | C4: 2 | D4: Belgium | E4: BE | F4: 2 | G4: IRB | H4: 2 | I4: [ 3M - 1Y ] | J4: 1100 | K4: Central banks and central governments | L4: 2 | M4: Defaulted assets | N4: 2 | O4: Non Performing | P4: 2 | Q4: Stage 2 | R4: 2 | S4: Non-guaranteed | V4: 2 | W4: Debt securities - including at amortised cost and fair value | X4: 2 | Y4: Yes | Z4: AT003 | AA4: Österreichische Volksbanken-Aktiengesellschaft | AB4: Österreichische Volksbanken-AG with credit institutions affiliated according to Article 10 of the CR | AC4: AT | AD4: CY | AE4: Cyprus
A5: 2 | B5: Baseline | C5: 3 | D5: Bulgaria | E5: BG | F5: 3 | G5: F-IRB | H5: 3 | I5: [ 1Y - 2Y ] | J5: 1110 | K5: Central banks | L5: 3 | M5: New defaulted assets | N5: 3 | O5: Performing but past due >30 days and <=90 days | P5: 3 | Q5: Stage 3 | V5: 3 | W5: Loans and advances - including at amortised cost and fair value | X5: 3 | Y5: Yes (static and dynamic) | Z5: AT005 | AA5: Raiffeisen Bank International | AB5: Raiffeisen Bank International AG | AC5: AT | AD5: DE | AE5: Germany
A6: 3 | B6: Adverse | C6: 4 | D6: Cyprus | E6: CY | F6: 4 | G6: A-IRB | H6: 4 | I6: [ 2Y - 3Y ] | J6: 1120 | K6: Central governments | L6: 4 | M6: Old defaulted assets | N6: 4 | O6: Non Performing and Defaulted | V6: 4 | W6: Off-Balance Sheet Exposures | X6: 4 | Y6: Yes (dynamic only) | Z6: AT006 | AA6: Raiffeisen Zentralbank Österreich | AB6: Raiffeisen Zentralbank Österreich AG | AC6: AT | AD6: DK | AE6: Denmark
A7: 4 | B7: Adverse Sovereign Shock | C7: 5 | D7: Czech Republic | E7: CZ | F7: 5 | G7: IM | H7: 5 | I7: [3Y - 5Y ] | J7: 1200 | K7: Regional governments or local authorities | N7: 5 | O7: Loans and advances subject to impairment | V7: 5 | W7: Loan commitments given | X7: 5 | Y7: Yes (static only) | Z7: AT008 | AA7: Raiffeisen-Holding NÖ-Wien | AB7: Raiffeisen-Holding Niederösterreich-Wien | AC7: AT | AD7: ES | AE7: Spain
C8: 6 | D8: Denmark | E8: DK | F8: 6 | G8: Fixed rate portfolio | H8: 6 | I8: [5Y - 10Y ] | J8: 1300 | K8: Public sector entities | N8: 11 | O8: Performing - of which exposures with forbearance measures | V8: 6 | W8: Cash balances at central banks and other demand deposits | Z8: AT009 | AA8: Raiffeisenlandesbank Oberösterreich | AB8: Raiffeisenlandesbank Oberösterreich AG | AC8: AT | AD8: FI | AE8: Finland
C9: 7 | D9: Estonia | E9: EE | F9: 7 | G9: Floating rate portfolio | H9: 7 | I9: [10Y - more ] | J9: 1400 | K9: Multilateral Development Banks | N9: 12 | O9: Performing Of which: Instruments with significant increase in credit risk since initial recognition but not credit-impaired (Stage 2) | V9: 7 | W9: Loans and advances - NFCs - of which: small and medium-sized enterprises at amortised cost | Z9: AT010 | AA9: Raiffeisen-Landesbanken-Holding | AB9: Raiffeisen-Landesbanken-Holding GmbH | AC9: AT | AD9: FR | AE9: France
C10: 8 | D10: Finland | E10: FI | F10: 10 | G10: SEC-IRBA securitisation – internal ratings-based approach | H10: 8 | I10: Total | J10: 1500 | K10: International Organisations | N10: 21 | O10: Non Performing Of which: exposures with forbearance measures | Z10: BE002 | AA10: AXA Bank Belgium | AB10: AXA Bank Belgium | AC10: BE | AD10: GB | AE10: United Kingdom
C11: 9 | D11: France | E11: FR | F11: 11 | G11: SEC-SA securitisation – standardised approach | J11: 1600 | K11: Central banks | N11: 22 | O11: Non Performing Of which: Unlikely to pay that are not past-due or past-due <= 90 days | Z11: BE004 | AA11: Belfius | AB11: Belfius Banque SA | AC11: BE | AD11: GR | AE11: Greece
C12: 10 | D12: Germany | E12: DE | F12: 12 | G12: SEC-ERBA securitisation – external ratings-based approach | J12: 1700 | K12: General governments | N12: 23 | O12: NON performing - of which Stage 3 | Z12: BE006 | AA12: Dexia | AB12: Dexia | AC12: BE | AD12: HU | AE12: Hungary
C13: 11 | D13: Greece | E13: GR | F13: 13 | G13: SEC-IAA securitisation – internal assessment approach | J13: 2000 | K13: Institutions | N13: 222 | O13: Non Performing Of which: Stage 2 | Z13: BE007 | AA13: Investar | AB13: Investar (Holding of Argenta Bank- en Verzekeringsgroep) | AC13: BE | AD13: IE | AE13: Ireland
C14: 12 | D14: Hungary | E14: HU | J14: 2100 | K14: Credit institutions | Z14: BE009 | AA14: KBC Groep | AB14: KBC Groep | AC14: BE | AD14: IT | AE14: Italy
C15: 13 | D15: Iceland | E15: IS | J15: 2200 | K15: Other financial corporations | Z15: CY001 | AA15: Bank of Cyprus | AB15: Bank of Cyprus Holdings Public Limited Company | AC15: CY | AD15: LU | AE15: Luxembourg
C16: 14 | D16: Ireland | E16: IE | J16: 3000 | K16: Corporates (Credit Risk) / Non Financial corporations (NPE- Forbearance) | Z16: CY002 | AA16: Co-operative Central Bank | AB16: Co -operative Central Bank Ltd | AC16: CY | AD16: LV | AE16: Latvia
C17: 15 | D17: Italy | E17: IT | J17: 3100 | K17: Corporates - Specialised Lending | Z17: CY003 | AA17: Hellenic Bank | AB17: Hellenic Bank Public Company Ltd | AC17: CY | AD17: MT | AE17: Malta
C18: 16 | D18: Latvia | E18: LV | J18: 3200 | K18: Corporates - SME | Z18: CY004 | AA18: Marfin Popular Bank | AB18: Marfin Popular Bank Public Co LTD | AC18: CY | AD18: NL | AE18: Netherlands
C19: 17 | D19: Liechtenstein | E19: LI | J19: 3300 | K19: Corporates - Other | Z19: DE001 | AA19: Aareal Bank | AB19: Aareal Bank AG | AC19: DE | AD19: NO | AE19: Norway
C20: 18 | D20: Lithuania | E20: LT | J20: 3310 | K20: Corporate excl. CRE (2011) | Z20: DE003 | AA20: Bayerische Landesbank | AB20: Bayerische Landesbank | AC20: DE | AD20: PL | AE20: Poland
C21: 19 | D21: Luxembourg | E21: LU | J21: 3330 | K21: Corporates - Of Which: SME general corporates (IRB) / Corporates - Other - SME (STA) | Z21: DE004 | AA21: Citigroup Global Markets Europe | AB21: Citigroup Global Markets Europe AG | AC21: DE | AD21: PT | AE21: Portgual
C22: 20 | D22: Malta | E22: MT | J22: 3500 | K22: Corporates - Purchased receivables | Z22: DE005 | AA22: Commerzbank | AB22: COMMERZBANK Aktiengesellschaft | AC22: DE | AD22: RO | AE22: Romania
C23: 21 | D23: Netherlands | E23: NL | J23: 3800 | K23: Corporates - Purchased receivables | Z23: DE006 | AA23: DekaBank | AB23: DekaBank Deutsche Girozentrale | AC23: DE | AD23: SE | AE23: Sweden
C24: 22 | D24: Norway | E24: NO | J24: 4000 | K24: Retail | Z24: DE007 | AA24: apoBank | AB24: DEUTSCHE APOTHEKER- UND ÄRZTEBANK EG | AC24: DE | AD24: SI | AE24: Slovenia
C25: 23 | D25: Poland | E25: PL | J25: 4100 | K25: Retail - Secured by real estate property | Z25: DE008 | AA25: Deutsche Bank | AB25: DEUTSCHE BANK AKTIENGESELLSCHAFT | AC25: DE
C26: 24 | D26: Portugal | E26: PT | J26: 4110 | K26: Retail - Secured by real estate property - SME | Z26: DE010 | AA26: Deutsche Postbank | AB26: Deutsche Postbank AG | AC26: DE
C27: 25 | D27: Romania | E27: RO | J27: 4120 | K27: Retail - Secured by real estate property - Non SME | Z27: DE011 | AA27: DZ Bank | AB27: DZ BANK AG Deutsche Zentral-Genossenschaftsbank, Frankfurt am Main | AC27: DE
C28: 26 | D28: Slovakia | E28: SK | J28: 4150 | K28: Retail - Secured by residential real estate | Z28: DE013 | AA28: Goldman Sachs Bank Europe | AB28: Goldman Sachs Bank Europe SE | AC28: DE
C29: 27 | D29: Slovenia | E29: SI | J29: 4200 | K29: Retail - Qualifying Revolving | Z29: DE014 | AA29: Hamburg Commercial Bank | AB29: Hamburg Commercial Bank AG | AC29: DE
C30: 28 | D30: Spain | E30: ES | J30: 4300 | K30: Retail - Other | Z30: DE015 | AA30: Haspa | AB30: HASPA Finanzholding | AC30: DE
C31: 29 | D31: Sweden | E31: SE | J31: 4310 | K31: Retail - Other - SME | Z31: DE018 | AA31: Hypo Real Estate | AB31: Hypo Real Estate Holding AG | AC31: DE
C32: 30 | D32: United Kingdom | E32: GB | J32: 4320 | K32: Retail - Other - Non SME | Z32: DE019 | AA32: IKB Deutsche Industriebank | AB32: IKB Deutsche Industriebank AG | AC32: DE
C33: 31 | D33: Brazil | E33: BR | J33: 4500 | K33: Retail - SME | Z33: DE020 | AA33: J.P. Morgan | AB33: J.P. Morgan SE | AC33: DE
C34: 32 | D34: Chile | E34: CL | J34: 4600 | K34: Retail excl. CRE (2011) | Z34: DE021 | AA34: KfW IPEX-Bank | AB34: KfW IPEX-Bank GmbH | AC34: DE
C35: 33 | D35: China | E35: CN | J35: 4700 | K35: Households | Z35: DE022 | AA35: LBBW | AB35: Landesbank Baden-Württemberg | AC35: DE
C36: 34 | D36: Croatia | E36: HR | J36: 4800 | K36: Retail - Purchased receivables | Z36: DE023 | AA36: Landesbank Berlin Holding | AB36: Landesbank Berlin Holding AG | AC36: DE
... C53: 55 | D53: Angola | E53: AO | J53: 9000 | K53: Exposures in default | Z53: DK004 | AA53: Sydbank | AB53: Sydbank | AC53: DK
C54: 56 | D54: Anguilla | E54: AI | Z54: ES001 | AA54: Abanca | AB54: Abanca Corporacion Bancaria, S.A. | AC54: ES
C55: 57 | D55: Antigua and Barbuda | E55: AG | Z55: ES002 | AA55: Banca March | AB55: Banca March | AC55: ES
C56: 58 | D56: Argentina | E56: AR | Z56: ES003 | AA56: BBVA | AB56: Banco Bilbao Vizcaya Argentaria, S.A. | AC56: ES
...

Sheet TE
A1: Value_Portfolio | B1: Label_Portfolio | C1: Value_Country | D1: Label_Country | E1: ISO2_Country | F1: Value_Financial_Instrument | G1: Label_Financial_Instrument | H1: Value_Status | I1: Label_Status | J1: Value_Perf_Status | K1: Label_Perf_Status | L1: Value_MKT_modprod | M1: Label_MKT_modprod | N1: Value_MKT_risk | O1: Label_MKT_risk | P1: Value_Accounting_Portfolio | Q1: Label_Accounting_Portfolio | R1: Value_Maturity | S1: Label_Maturity | T1: Value_Asset_Stages | U1: Label_Asset_Stages | V1: Value_Asset_FV | W1: Label_Asset_FV | X1: Value_NACE | Y1: Label_NACE | Z1: Value_Fin_End_Year | AA1: Label_Fin_End_Year | AB1: Value_Exposure | AC1: Label_Exposure | AD1: Value_Perf_Forborne | AE1: Label_Perf_Forborne | AF1: Bank_ID | AG1: Name | AH1: Name_EBA | AI1: Bank_ISO2 | AJ1: ISO2 | AK1: Country
A2: 0 | B2: Total / No breakdown by portfolio | C2: 0 | D2: Total / No Breakdown | E2: TOT | F2: 0 | G2: Total / No breakdown | H2: 0 | I2: No breakdown by status | J2: 0 | K2: No breakdown by Perf_status | L2: 0 | M2: No breakdown by MKT_Modprod | N2: 0 | O2: No breakdown by MKT_Risk | P2: 0 | Q2: No breakdown by Accounting_portfolio | R2: 0 | S2: No breakdown by maturity | T2: 0 | U2: No breakdown by ASSETS_Stages | V2: 0 | W2: No breakdown by ASSETS_FV | X2: 0 | Y2: No breakdown by NACE_codes | Z2: 0 | AA2: 31-Dec | AB2: 0 | AC2: Total / No breakdown | AD2: 0 | AE2: Total / No Breakdown | AF2: AT001 | AG2: BAWAG | AH2: BAWAG Group AG | AI2: AT | AJ2: AT | AK2: =VLOOKUP(AJ2,Dictionary!$D:$E,2,FALSE) -> Austria
A3: 1 | B3: SA | C3: 1 | D3: Austria | E3: AT | F3: 12 | G3: Derivatives | H3: 1 | I3: Non defaulted assets | J3: 1 | K3: Performing | L3: 1 | M3: Traded debt instruments | N3: 1 | O3: General risk | P3: 1 | Q3: Held for trading | R3: 1 | S3: [ 0 - 3M [ | T3: 1 | U3: Stage 1: Assets without significant increase in credit risk since initial recognition | V3: 1 | W3: Fair value hierarchy: Level 1 | X3: 1 | Y3: A Agriculture, forestry and fishing | Z3: 1 | AA3: 31-Mar | AB3: 101 | AC3: Central banks | AD3: 1 | AE3: Debt Instruments - other than HFT | AF3: AT002 | AG3: Erste Group | AH3: Erste Group Bank AG | AI3: AT | AJ3: BE | AK3: =VLOOKUP(AJ3,Dictionary!$D:$E,2,FALSE) -> Belgium
A4: 2 | B4: IRB | C4: 2 | D4: Belgium | E4: BE | F4: 21 | G4: Short positions - Equity instruments | H4: 2 | I4: Defaulted assets | J4: 11 | K4: Performing - of which exposures with forbearance measures | L4: 2 | M4: Equities | N4: 2 | O4: Specific risk | P4: 2 | Q4: Designated at fair value through profit or loss | R4: 2 | S4: [ 3M - 1Y [ | T4: 2 | U4: Stage 2: Assets with significant increase in credit risk since initial recognition but not credit-impaired | V4: 2 | W4: Fair value hierarchy: Level 2 | X4: 2 | Y4: B Mining and quarrying | Z4: 2 | AA4: 30-Jun | AB4: 102 | AC4: General governments | AD4: 2 | AE4: Debt securities - including at amortised cost and fair value | AF4: AT004 | AG4: Promontoria Sacher Holding | AH4: Promontoria Sacher Holding N.V. | AI4: AT | AJ4: BG | AK4: =VLOOKUP(AJ4,Dictionary!$D:$E,2,FALSE) -> Bulgaria
A5: 3 | B5: F-IRB | C5: 3 | D5: Bulgaria | E5: BG | F5: 22 | G5: Short positions - Debt securities | H5: 3 | I5: New defaulted assets | J5: 12 | K5: Performing Of which: Instruments with significant increase in credit risk since initial recognition but not credit-impaired (Stage 2) | L5: 3 | M5: Foreign Exchange risk | P5: 3 | Q5: Available-for-sale | R5: 3 | S5: [ 1Y - 2Y [ | T5: 3 | U5: Stage 3: Credit-impaired assets | V5: 3 | W5: Fair value hierarchy: Level 3 | X5: 3 | Y5: C Manufacturing | Z5: 3 | AA5: 30-Sep | AB5: 103 | AC5: Central governments or central banks | AD5: 3 | AE5: Loans and advances - including at amortised cost and fair value | AF5: AT005 | AG5: Raiffeisen Bank International | AH5: Raiffeisen Bank International AG | AI5: AT | AJ5: CY | AK5: =VLOOKUP(AJ5,Dictionary!$D:$E,2,FALSE) -> Cyprus
A6: 4 | B6: A-IRB | C6: 4 | D6: Cyprus | E6: CY | F6: 30 | G6: Deposits | H6: 4 | I6: Old defaulted assets | J6: 2 | K6: Non Performing | L6: 4 | M6: Commodity risk | P6: 4 | Q6: Loans and Receivables | R6: 4 | S6: [ 2Y - 3Y [ | X6: 4 | Y6: D Electricity, gas, steam and air conditioning supply | AB6: 104 | AC6: Regional governments or local authorities | AD6: 4 | AE6: Off-Balance Sheet Exposures | AF6: AT007 | AG6: Raiffeisen Bankengruppe OÖ | AH6: Raiffeisenbankengruppe OÖ Verbund eGen | AI6: AT | AJ6: DE | AK6: =VLOOKUP(AJ6,Dictionary!$D:$E,2,FALSE) -> Germany
A7: 5 | B7: IM | C7: 5 | D7: Czech Republic | E7: CZ | F7: 31 | G7: Deposits - of which: Current accounts / overnight deposits | J7: 21 | K7: Non Performing Of which: exposures with forbearance measures | P7: 5 | Q7: Held-to-maturity investments | R7: 5 | S7: [3Y - 5Y [ | X7: 5 | Y7: E Water supply | AB7: 105 | AC7: Public sector entities | AD7: 5 | AE7: Loan commitments given | AF7: AT008 | AG7: Raiffeisen-Holding NÖ-Wien | AH7: Raiffeisen-Holding Niederösterreich-Wien | AI7: AT | AJ7: DK | AK7: =VLOOKUP(AJ7,Dictionary!$D:$E,2,FALSE) -> Denmark
A8: 6 | B8: Fixed rate portfolio | C8: 6 | D8: Denmark | E8: DK | F8: 40 | G8: Debt securities issued | J8: 22 | K8: Non Performing Of which: Unlikely to pay that are not past-due or past-due <= 90 days | R8: 6 | S8: [5Y - 10Y [ | X8: 6 | Y8: F Construction | AB8: 106 | AC8: Multilateral Development Banks | AD8: 6 | AE8: Cash balances at central banks and other demand deposits | AF8: AT010 | AG8: Raiffeisen-Landesbanken-Holding | AH8: Raiffeisen-Landesbanken-Holding GmbH | AI8: AT | AJ8: EE | AK8: =VLOOKUP(AJ8,Dictionary!$D:$E,2,FALSE) -> Estonia
A9: 7 | B9: Floating rate portfolio | C9: 7 | D9: Estonia | E9: EE | F9: 41 | G9: Debt securities issued Of which: Subordinated Debt securities issued | J9: 222 | K9: Non Performing Of which: Stage 2 | R9: 7 | S9: [10Y - more | X9: 7 | Y9: G Wholesale and retail trade | AB9: 107 | AC9: International Organisations | AD9: 7 | AE9: Loans and advances - NFCs - of which: small and medium-sized enterprises at amortised cost | AF9: AT011 | AG9: Sberbank Europe Group | AH9: Sberbank Europe AG | AI9: AT | AJ9: ES | AK9: =VLOOKUP(AJ9,Dictionary!$D:$E,2,FALSE) -> Spain
A10: 10 | B10: SEC-IRBA securitisation – internal ratings-based approach | C10: 8 | D10: Finland | E10: FI | F10: 50 | G10: Other financial liabilities | J10: 23 | K10: NON performing - of which Stage 3 | R10: 8 | S10: Total | X10: 8 | Y10: H Transport and storage | AB10: 201 | AC10: Credit institutions | AF10: AT012 | AG10: VTB Bank Austria | AH10: VTB Bank (Austria) AG | AI10: AT | AJ10: FI | AK10: =VLOOKUP(AJ10,Dictionary!$D:$E,2,FALSE) -> Finland
A11: 11 | B11: SEC-SA securitisation – standardised approach | C11: 9 | D11: France | E11: FR | J11: 3 | K11: Performing but past due >30 days and <=90 days | X11: 9 | Y11: I Accommodation and food service activities | AB11: 202 | AC11: Financial corporations other than credit institutions | AF11: AT014 | AG11: Volksbank Wien | AH11: Volksbank Wien AG | AI11: AT | AJ11: FR | AK11: =VLOOKUP(AJ11,Dictionary!$D:$E,2,FALSE) -> France
A12: 12 | B12: SEC-ERBA securitisation – external ratings-based approach | C12: 10 | D12: Germany | E12: DE | J12: 4 | K12: Non Performing and Defaulted | X12: 10 | Y12: J Information and communication | AB12: 203 | AC12: Institutions | AF12: BE002 | AG12: AXA Bank Belgium | AH12: AXA Bank Belgium | AI12: BE | AJ12: GB | AK12: =VLOOKUP(AJ12,Dictionary!$D:$E,2,FALSE) -> United Kingdom
A13: 13 | B13: SEC-IAA securitisation – internal assessment approach | C13: 11 | D13: Greece | E13: GR | J13: 5 | K13: Loans and advances subject to impairment | X13: 11 | Y13: K Financial and insurance activities | AB13: 204 | AC13: Institutions without a short-term credit assessment | AF13: BE004 | AG13: Belfius | AH13: Belfius Banque SA | AI13: BE | AJ13: GR | AK13: =VLOOKUP(AJ13,Dictionary!$D:$E,2,FALSE) -> Greece
C14: 12 | D14: Hungary | E14: HU | X14: 12 | Y14: L Real estate activities | AB14: 301 | AC14: Non-financial corporations | AF14: BE005 | AG14: Crelan | AH14: Crelan | AI14: BE | AJ14: HU | AK14: =VLOOKUP(AJ14,Dictionary!$D:$E,2,FALSE) -> Hungary
C15: 13 | D15: Iceland | E15: IS | X15: 13 | Y15: M Professional, scientific and technical activities | AB15: 302 | AC15: Corporates - SME | AF15: BE006 | AG15: Dexia | AH15: Dexia | AI15: BE | AJ15: IE | AK15: =VLOOKUP(AJ15,Dictionary!$D:$E,2,FALSE) -> Ireland
C16: 14 | D16: Ireland | E16: IE | X16: 14 | Y16: N Administrative and support service activities | AB16: 303 | AC16: Corporates | AF16: BE008 | AG16: Investeringsmaatschappij Argenta | AH16: Investeringsmaatschappij Argenta | AI16: BE | AJ16: IS | AK16: =VLOOKUP(AJ16,Dictionary!$D:$E,2,FALSE) -> Iceland
C17: 15 | D17: Italy | E17: IT | X17: 15 | Y17: O Public administration and defence, compulsory social security | AB17: 304 | AC17: Corporates - Specialised Lending | AF17: BE009 | AG17: KBC Groep | AH17: KBC Groep | AI17: BE | AJ17: IT | AK17: =VLOOKUP(AJ17,Dictionary!$D:$E,2,FALSE) -> Italy
C18: 16 | D18: Latvia | E18: LV | X18: 16 | Y18: P Education | AB18: 305 | AC18: Corporates other than specialised lending | AF18: BE010 | AG18: BNY | AH18: The Bank of New York Mellon | AI18: BE | AJ18: LI | AK18: =VLOOKUP(AJ18,Dictionary!$D:$E,2,FALSE) -> Liechtenstein
C19: 17 | D19: Liechtenstein | E19: LI | X19: 17 | Y19: Q Human health services and social work activities | AB19: 306 | AC19: Corporates without a short-term credit assessment | AF19: BG001 | AG19: First Investment Bank | AH19: First Investment Bank | AI19: BG | AJ19: LT | AK19: =VLOOKUP(AJ19,Dictionary!$D:$E,2,FALSE) -> Lithuania
C20: 18 | D20: Lithuania | E20: LT | X20: 18 | Y20: R Arts, entertainment and recreation | AB20: 307 | AC20: Institutions and corporates with a short-term credit assessment | AF20: CY001 | AG20: Bank of Cyprus | AH20: Bank of Cyprus Holdings Public Limited Company | AI20: CY | AJ20: LU | AK20: =VLOOKUP(AJ20,Dictionary!$D:$E,2,FALSE) -> Luxembourg
C21: 19 | D21: Luxembourg | E21: LU | X21: 19 | Y21: S Other services | AB21: 308 | AC21: Corporates - Commercial real estate | AF21: CY002 | AG21: Co-operative Central Bank | AH21: Co -operative Central Bank Ltd | AI21: CY | AJ21: SI | AK21: =VLOOKUP(AJ21,Dictionary!$D:$E,2,FALSE) -> Slovenia
C22: 20 | D22: Malta | E22: MT | AB22: 311 | AC22: Non-financial corporations - Small and Medium-sized Enterprises | AF22: CY003 | AG22: Hellenic Bank | AH22: Hellenic Bank Public Company Ltd | AI22: CY | AJ22: LV | AK22: =VLOOKUP(AJ22,Dictionary!$D:$E,2,FALSE) -> Latvia
C23: 21 | D23: Netherlands | E23: NL | AB23: 312 | AC23: Non-financial corporations - Collateralised by commercial immovable property | AF23: CY005 | AG23: RCB Bank | AH23: RCB Bank Ltd | AI23: CY | AJ23: MT | AK23: =VLOOKUP(AJ23,Dictionary!$D:$E,2,FALSE) -> Malta
C24: 22 | D24: Norway | E24: NO | AB24: 401 | AC24: Households | AF24: DE001 | AG24: Aareal Bank | AH24: Aareal Bank AG | AI24: DE | AJ24: NL | AK24: =VLOOKUP(AJ24,Dictionary!$D:$E,2,FALSE) -> Netherlands
C25: 23 | D25: Poland | E25: PL | AB25: 402 | AC25: Residential real estate | AF25: DE002 | AG25: Atlantic Lux HoldCo | AH25: ATLANTIC LUX HOLDCO S.A R.L. | AI25: DE | AJ25: NO | AK25: =VLOOKUP(AJ25,Dictionary!$D:$E,2,FALSE) -> Norway
C26: 24 | D26: Portugal | E26: PT | AB26: 403 | AC26: Credit for consumption | AF26: DE003 | AG26: Bayerische Landesbank | AH26: Bayerische Landesbank | AI26: DE | AJ26: PL | AK26: =VLOOKUP(AJ26,Dictionary!$D:$E,2,FALSE) -> Poland
C27: 25 | D27: Romania | E27: RO | AB27: 404 | AC27: Retail | AF27: DE004 | AG27: Citigroup Global Markets Europe | AH27: Citigroup Global Markets Europe AG | AI27: DE | AJ27: PT | AK27: =VLOOKUP(AJ27,Dictionary!$D:$E,2,FALSE) -> Portgual
C28: 26 | D28: Slovakia | E28: SK | AB28: 405 | AC28: Retail - SME | AF28: DE005 | AG28: Commerzbank | AH28: COMMERZBANK Aktiengesellschaft | AI28: DE | AJ28: RO | AK28: =VLOOKUP(AJ28,Dictionary!$D:$E,2,FALSE) -> Romania
C29: 27 | D29: Slovenia | E29: SI | AB29: 406 | AC29: Retail - Secured by real estate property | AF29: DE006 | AG29: DekaBank | AH29: DekaBank Deutsche Girozentrale | AI29: DE | AJ29: SE | AK29: =VLOOKUP(AJ29,Dictionary!$D:$E,2,FALSE) -> Sweden
C30: 28 | D30: Spain | E30: ES | AB30: 407 | AC30: Retail - Secured by real estate property - SME | AF30: DE007 | AG30: apoBank | AH30: DEUTSCHE APOTHEKER- UND ÄRZTEBANK EG | AI30: DE | AJ30: OT | AK30: Other
C31: 29 | D31: Sweden | E31: SE | AB31: 408 | AC31: Retail - Secured by real estate property - Non SME | AF31: DE008 | AG31: Deutsche Bank | AH31: DEUTSCHE BANK AKTIENGESELLSCHAFT | AI31: DE | AJ31: XX | AK31: Other
C32: 30 | D32: United Kingdom | E32: GB | AB32: 409 | AC32: Retail - Qualifying revolving | AF32: DE009 | AG32: Deutsche Pfandbriefbank | AH32: Deutsche Pfandbriefbank AG | AI32: DE
C33: 31 | D33: Brazil | E33: BR | AB33: 410 | AC33: Retail - Other retail | AF33: DE011 | AG33: DZ Bank | AH33: DZ BANK AG Deutsche Zentral-Genossenschaftsbank, Frankfurt am Main | AI33: DE
C34: 32 | D34: Chile | E34: CL | AB34: 411 | AC34: Retail - Other retail - SME | AF34: DE012 | AG34: Sparkassen-Finanzgruppe | AH34: Erwerbsgesellschaft der S-Finanzgruppe mbH & Co. KG | AI34: DE
C35: 33 | D35: China | E35: CN | AB35: 412 | AC35: Retail - Other retail - Non SME | AF35: DE013 | AG35: Goldman Sachs Bank Europe | AH35: Goldman Sachs Bank Europe SE | AI35: DE
C36: 34 | D36: Croatia | E36: HR | AB36: 431 | AC36: Households - of which collateralised by residential immovable property | AF36: DE014 | AG36: Hamburg Commercial Bank | AH36: Hamburg Commercial Bank AG | AI36: DE
C37: 35 | D37: Hong Kong | E37: HK | AB37: 432 | AC37: Households - of which credit for consumption | AF37: DE015 | AG37: Haspa | AH37: HASPA Finanzholding | AI37: DE
C38: 36 | D38: India | E38: IN | AB38: 501 | AC38: Secured by mortgages on immovable property | AF38: DE016 | AG38: HSBC Germany | AH38: HSBC Germany Holdings GmbH | AI38: DE
C39: 37 | D39: Japan | E39: JP | AB39: 502 | AC39: Secured by mortgages on immovable property - SME | AF39: DE017 | AG39: HSH Beteiligungs Management | AH39: HSH Beteiligungs Management GmbH | AI39: DE
C40: 38 | D40: Mexico | E40: MX | AB40: 601 | AC40: Exposures in default | AF40: DE018 | AG40: Hypo Real Estate | AH40: Hypo Real Estate Holding AG | AI40: DE
...

Sheet SSM
A1: Value_Scenario | B1: Label_Scenario | C1: Value_Range_SSM001_SSM002 | D1: Label_Range_SSM001_SSM002 | E1: Value_Range_SSM003_SSM004 | F1: Label_Range_SSM003_SSM004 | G1: Value_Range_SSM005_SSM006 | H1: Label_Range_SSM005_SSM006 | I1: Bank_ID | J1: Name | K1: Name_EBA | L1: Bank_ISO2 | M1: ISO2 | N1: Country
A2: 0 | B2: No breakdown | C2: 1 | D2: < 300bps | E2: 1 | F2: CET1R < 8% | G2: 1 | H2: LR < 4% | I2: AT001 | J2: BAWAG | K2: BAWAG Group AG | L2: AT | M2: AT | N2: =VLOOKUP(M2,Dictionary!$D:$E,2,FALSE) -> Austria
A3: 1 | B3: Actual | C3: 2 | D3: 300 to 599 bps | E3: 2 | F3: 8% ≤ CET1R < 11% | G3: 2 | H3: 4% ≤ LR < 5% | I3: AT007 | J3: Raiffeisen Bankengruppe OÖ | K3: Raiffeisenbankengruppe OÖ Verbund eGen | L3: AT | M3: BE | N3: =VLOOKUP(M3,Dictionary!$D:$E,2,FALSE) -> Belgium
A4: 11 | B4: Actual restated | C4: 3 | D4: 600 to 899 bps | E4: 3 | F4: 11% ≤ CET1R < 14% | G4: 3 | H4: 5% ≤ LR < 6% | I4: AT011 | J4: Sberbank Europe Group | K4: Sberbank Europe AG | L4: AT | M4: CY | N4: =VLOOKUP(M4,Dictionary!$D:$E,2,FALSE) -> Cyprus
A5: 2 | B5: Baseline | C5: 4 | D5: > 900bps | E5: 4 | F5: CET1R ≥ 14% | G5: 4 | H5: LR ≥ 6% | I5: AT013 | J5: Addiko Bank | K5: Addiko Bank AG | L5: AT | M5: DE | N5: =VLOOKUP(M5,Dictionary!$D:$E,2,FALSE) -> Germany
A6: 3 | B6: Adverse | I6: AT014 | J6: Volksbank Wien | K6: Volksbank Wien AG | L6: AT | M6: EE | N6: =VLOOKUP(M6,Dictionary!$D:$E,2,FALSE) -> Estonia
A7: 4 | B7: Adverse Sovereign Shock | I7: BE001 | J7: Argenta Groep | K7: Argenta Bank- en Verzekeringsgroep NV | L7: BE | M7: ES | N7: =VLOOKUP(M7,Dictionary!$D:$E,2,FALSE) -> Spain
I8: BE002 | J8: AXA Bank Belgium | K8: AXA Bank Belgium | L8: BE | M8: FI | N8: =VLOOKUP(M8,Dictionary!$D:$E,2,FALSE) -> Finland
I9: BE003 | J9: Degroof Petercam | K9: Banque Degroof Petercam SA | L9: BE | M9: FR | N9: =VLOOKUP(M9,Dictionary!$D:$E,2,FALSE) -> France
I10: BE005 | J10: Crelan | K10: Crelan | L10: BE | M10: GR | N10: =VLOOKUP(M10,Dictionary!$D:$E,2,FALSE) -> Greece
I11: BE010 | J11: BNY | K11: The Bank of New York Mellon | L11: BE | M11: IE | N11: =VLOOKUP(M11,Dictionary!$D:$E,2,FALSE) -> Ireland
I12: CY001 | J12: Bank of Cyprus | K12: Bank of Cyprus Holdings Public Limited Company | L12: CY | M12: IT | N12: =VLOOKUP(M12,Dictionary!$D:$E,2,FALSE) -> Italy
I13: CY003 | J13: Hellenic Bank | K13: Hellenic Bank Public Company Ltd | L13: CY | M13: LT | N13: =VLOOKUP(M13,Dictionary!$D:$E,2,FALSE) -> Lithuania
I14: CY005 | J14: RCB Bank | K14: RCB Bank Ltd | L14: CY | M14: LU | N14: =VLOOKUP(M14,Dictionary!$D:$E,2,FALSE) -> Luxembourg
I15: DE001 | J15: Aareal Bank | K15: Aareal Bank AG | L15: DE | M15: LV | N15: =VLOOKUP(M15,Dictionary!$D:$E,2,FALSE) -> Latvia
I16: DE006 | J16: DekaBank | K16: DekaBank Deutsche Girozentrale | L16: DE | M16: MT | N16: =VLOOKUP(M16,Dictionary!$D:$E,2,FALSE) -> Malta
I17: DE007 | J17: apoBank | K17: DEUTSCHE APOTHEKER- UND ÄRZTEBANK EG | L17: DE | M17: NL | N17: =VLOOKUP(M17,Dictionary!$D:$E,2,FALSE) -> Netherlands
I18: DE009 | J18: Deutsche Pfandbriefbank | K18: Deutsche Pfandbriefbank AG | L18: DE | M18: PT | N18: =VLOOKUP(M18,Dictionary!$D:$E,2,FALSE) -> Portgual
I19: DE012 | J19: Sparkassen-Finanzgruppe | K19: Erwerbsgesellschaft der S-Finanzgruppe mbH & Co. KG | L19: DE | M19: SI | N19: =VLOOKUP(M19,Dictionary!$D:$E,2,FALSE) -> Slovenia
I20: DE014 | J20: Hamburg Commercial Bank | K20: Hamburg Commercial Bank AG | L20: DE
I21: DE015 | J21: Haspa | K21: HASPA Finanzholding | L21: DE
I22: DE028 | J22: Münchener Hypothekenbank | K22: Münchener Hypothekenbank eG | L22: DE
I23: DE031 | J23: State Street Europe Holdings Germany | K23: State Street Europe Holdings Germany S.a.r.l. & Co. KG | L23: DE
I24: DE038 | J24: UBS Europe SE | K24: UBS Europe SE | L24: DE
I25: EE001 | J25: LHV | K25: AS LHV Group | L25: EE
I26: EE002 | J26: Luminor Bank | K26: Luminor Holding AS | L26: EE
I27: ES001 | J27: Abanca | K27: Abanca Corporacion Bancaria, S.A. | L27: ES
I28: ES004 | J28: Banco de Crédito Cooperativo | K28: Banco de Crédito Social Cooperativo | L28: ES
I29: ES029 | J29: Ibercaja | K29: Ibercaja Banco, S.A. | L29: ES
I30: ES030 | J30: Kutxabank | K30: Kutxabank, S.A. | L30: ES
I31: FI001 | J31: Kuntarahoitus | K31: Kuntarahoitus Oyj | L31: FI
... I68: SI004 | J68: NLB Skupina | K68: Nova Ljubljanska Banka d.d., Ljubljana | L68: SI

Sheet Common_Exposure
A1: Exposure | B1: Exposure_Label | C1: Common_Exposure
A2: 0 | B2: Total / No breakdown | C2: C000
A3: 101 | B3: Central banks
A4: 102 | B4: General governments
A5: 103 | B5: Central governments or central banks | C5: C103
A6: 104 | B6: Regional governments or local authorities | C6: C104
A7: 105 | B7: Public sector entities | C7: C105
A8: 106 | B8: Multilateral Development Banks | C8: C106
A9: 107 | B9: International Organisations | C9: C107
A10: 201 | B10: Credit institutions
A11: 202 | B11: Financial corporations other than credit institutions
A12: 203 | B12: Institutions | C12: C203
A13: 204 | B13: Institutions without a short-term credit assessment
A14: 301 | B14: Non-financial corporations
A15: 302 | B15: Corporates - SME | C15: C302
A16: 303 | B16: Corporates | C16: C303
A17: 304 | B17: Corporates - Specialised Lending | C17: C304
A18: 305 | B18: Corporates other than specialised lending
A19: 306 | B19: Corporates without a short-term credit assessment
A20: 307 | B20: Institutions and corporates with a short-term credit assessment
A21: 308 | B21: Corporates - Commercial real estate
A22: 311 | B22: Non-financial corporations - Small and Medium-sized Enterprises
A23: 312 | B23: Non-financial corporations - Collateralised by commercial immovable property
A24: 401 | B24: Households
A25: 402 | B25: Residential real estate
A26: 403 | B26: Credit for consumption
A27: 404 | B27: Retail | C27: C404
A28: 405 | B28: Retail - SME | C28: C405
A29: 406 | B29: Retail - Secured by real estate property | C29: C406
A30: 407 | B30: Retail - Secured by real estate property - SME | C30: C407
A31: 408 | B31: Retail - Secured by real estate property - Non SME | C31: C408
A32: 409 | B32: Retail - Qualifying revolving | C32: C409
A33: 410 | B33: Retail - Other retail | C33: C410
A34: 411 | B34: Retail - Other retail - SME | C34: C411
A35: 412 | B35: Retail - Other retail - Non SME | C35: C412
A36: 431 | B36: Households - of which collateralised by residential immovable property
A37: 432 | B37: Households - of which credit for consumption
A38: 501 | B38: Secured by mortgages on immovable property | C38: C501
A39: 601 | B39: Exposures in default | C39: C601
A40: 602 | B40: Items associated with particularly high risk | C40: C602
...

Sheet Selection
A1: Common | B1: ST_2010 | C1: ST_2011 | D1: ST_2014 | E1: ST_2016 | F1: ST_2018 | G1: ST_2021 | H1: ST_2023 | I1: ST_2025 | J1: Order | K1: Sign | L1: RM | M1: CET1_RWA_FL
A2: ITM_67 | B2: 10001 | C2: 30014 | D2: 993402 | E2: 1690802 | F2: 183702 | G2: 213702 | H2: 2337002 | I2: 2537002 | J2: 1 | K2: 1 | L2: 0 | M2: 1690802
A3: ITM_35 | B3: 10003 | C3: 30016 | D3: 993434 | E3: 1690845 | F3: 183756 | G3: 213508 | H3: 2335008 | I3: 2535008 | J3: 2 | K3: 1 | L3: 0 | M3: 1690818
A4: ITM_175 | F4: 183758 | J4: 2 | K4: 1 | L4: 1 | M4: 1690827
A5: ITM_119 | B5: 10008 | C5: 30015 | D5: 993441 | E5: 1690847 | F5: 183759 | G5: 213761 | H5: 2337061 | I5: 2537061 | J5: 3 | K5: 1 | L5: 0 | M5: 1690835
M6: 1690818
A7: ITM_122 | B7: 10001 | C7: 30014 | D7: 1400000 | E7: 1600000 | F7: 183762 | G7: 213764 | H7: 2337064 | I7: 2537064 | J7: 4 | K7: 1 | L7: 0 | M7: 1690837
A8: ITM_36 | B8: 10003 | C8: 30016 | D8: 1400001 | E8: 1600001 | F8: 183756 | G8: 213509 | H8: 2335009 | I8: 2535009 | J8: 5 | K8: 1 | L8: 0 | M8: 1690839
A9: ITM_174 | F9: 183757 | J9: 5 | K9: -1 | L9: 1 | M9: 1690841
A10: ITM_125 | B10: 10008 | C10: 30015 | D10: 1400002 | E10: 1690850 | F10: 183765 | G10: 213767 | H10: 2337067 | I10: 2537067 | J10: 6 | K10: 1 | L10: 0 | M10: 1690837
M11: 1690844
A12: ITM_122 | B12: 10001 | C12: 30014 | D12: 1400000 | E12: 1600000 | F12: 183762 | G12: 213764 | H12: 2337064 | I12: 2537064 | J12: 7 | K12: 1 | L12: 0 | M12: 1690845
A13: ITM_36 | B13: 10003 | C13: 30016 | D13: 1400001 | E13: 1600001 | F13: 183756 | G13: 213509 | H13: 2335009 | I13: 2535009 | J13: 8 | K13: 1 | L13: 0 | M13: 1690846
A14: ITM_174 | F14: 183757 | J14: 8 | K14: -1 | L14: 1 | M14: 993402
A15: ITM_125 | B15: 10008 | C15: 30015 | D15: 1400002 | E15: 1690850 | F15: 183765 | G15: 213767 | H15: 2337067 | I15: 2537067 | J15: 9 | K15: 1 | L15: 0 | M15: 993419
M16: 993426
A17: ITM_67 | B17: 10001 | C17: 30014 | D17: 993402 | E17: 1690802 | F17: 183702 | G17: 213702 | H17: 2337002 | I17: 2537002 | J17: 10 | K17: 1 | L17: 0 | M17: 993430
A18: ITM_35 | B18: 10003 | C18: 30016 | D18: 993434 | E18: 1690845 | F18: 183756 | G18: 213508 | H18: 2335008 | I18: 2535008 | J18: 11 | K18: 1 | L18: 0 | M18: 993419
A19: ITM_175 | F19: 183758 | J19: 11 | K19: 1 | L19: 1 | M19: 993433
A20: ITM_119 | B20: 10008 | C20: 30015 | D20: 993441 | E20: 1690847 | F20: 183759 | G20: 213761 | H20: 2337061 | I20: 2537061 | J20: 12 | K20: 1 | L20: 0 | M20: 993434
A21: ITM_57 | B21: 10050 | C21: 30047 | D21: 993012 | E21: 1690712 | F21: 183612 | G21: 213612 | H21: 2336012 | I21: 2536012 | J21: 13 | K21: 1 | L21: 0
A22: ITM_56 | C22: 30048 | J22: 13 | K22: 1 | L22: 0
A23: ITM_386 | B23: 10009 | J23: 14 | K23: 1 | L23: 0
A24: ITM_1 | C24: 30040 | D24: 993001 | E24: 1690701 | F24: 183101 | G24: 213101 | H24: 2331001 | I24: 2531001 | J24: 15 | K24: 1 | L24: 0
A25: ITM_50 | E25: 1690705 | F25: 183605 | G25: 213605 | H25: 2336005 | I25: 2536005 | J25: 16 | K25: 1 | L25: 0
A27: ITM_55 | B27: 10010 | C27: 30046 | D27: 993007 | E27: 1690710 | F27: 183610 | G27: 213610 | H27: 2336010 | I27: 2536010 | J27: 17 | K27: 1 | L27: 0
A28: ITM_51 | B28: 10011 | C28: 30041 | D28: 993002 | E28: 1690706 | F28: 183606 | G28: 213606 | H28: 2336006 | I28: 2536006 | J28: 18 | K28: 1 | L28: 0
A29: ITM_72 | D29: 993407 | E29: 1690807 | F29: 183707 | G29: 213707 | H29: 2337007 | I29: 2537007 | J29: 19 | K29: 1 | L29: 0
A30: ITM_253 | D30: 993408 | E30: 1690808 | J30: 19 | K30: 1 | L30: 1
A31: ITM_52 | D31: 993008 | E31: 1690707 | F31: 183607 | G31: 213607 | H31: 2336007 | I31: 2536007 | J31: 20 | K31: 1 | L31: 0
A32: ITM_271 | D32: 993009 | J32: 20 | K32: 1 | L32: 0
A33: ITM_79 | C33: 31013 | D33: 993412 | E33: 1690812 | F33: 183713 | G33: 213714 | H33: 2337014 | I33: 2537014 | J33: 21 | K33: 1 | L33: 0
A34: ITM_71 | D34: 993406 | E34: 1690806 | F34: 183706 | G34: 213706 | H34: 2337006 | I34: 2537006 | J34: 22 | K34: 1 | L34: 0
A35: ITM_61 | C35: 30051 | D35: 993017 | E35: 1690717 | F35: 183616 | G35: 213616 | H35: 2336016 | I35: 2536016 | J35: 23 | K35: 1 | L35: 0
A38: ITM_67 | B38: 10001 | C38: 30014 | D38: 993402 | E38: 1690802 | F38: 183702 | G38: 213702 | H38: 2337002 | I38: 2537002 | J38: 24 | K38: 1 | L38: 0
A39: ITM_35 | B39: 10003 | C39: 30016 | D39: 993434 | E39: 1690845 | F39: 183756 | G39: 213508 | H39: 2335008 | I39: 2535008 | J39: 25 | K39: 1 | L39: 0
A40: ITM_175 | F40: 183758 | J40: 25 | K40: 1 | L40: 1
A41: ITM_119 | B41: 10008 | C41: 30015 | D41: 993441 | E41: 1690847 | F41: 183759 | G41: 213761 | H41: 2337061 | I41: 2537061 | J41: 26 | K41: 1 | L41: 0
A43: ITM_122 | B43: 10001 | C43: 30014 | D43: 1400000 | E43: 1600000 | F43: 183762 | G43: 213764 | H43: 2337064 | I43: 2537064 | J43: 27 | K43: 1 | L43: 0
A44: ITM_36 | B44: 10003 | C44: 30016 | D44: 1400001 | E44: 1600001 | F44: 183756 | G44: 213509 | H44: 2335009 | I44: 2535009 | J44: 28 | K44: 1 | L44: 0
...

Sheet Labels
A1: Category | B1: Common_Item | C1: Label | D1: Annual | E1: Ratio | F1: Order | G1: Measure
A2: Capital Adequacy | B2: ITM_119 | C2: Transitional Common Equity Tier 1 Capital Ratio (%) | D2: 0 | E2: 1 | F2: 1 | G2: %
A3: Capital Adequacy | B3: ITM_67 | C3: Transitional Common Equity Tier 1 Capital (EURm) | D3: 0 | E3: 0 | F3: 2 | G3: EURm
A4: Capital Adequacy | B4: ITM_170 | C4: Transitional Total Risk Exposure Amounts (EURm) | D4: 0 | E4: 0 | F4: 3 | G4: EURm
A5: Capital Adequacy | B5: ITM_RWA | C5: Transitional Risk Exposure Amounts Breakdown (%) | D5: 0 | E5: 1 | F5: 4 | G5: %
A6: Capital Adequacy | B6: ITM_CETFL | C6: Fully-Loaded Common Equity Tier 1 Capital Ratio (%) | D6: 0 | E6: 1 | F6: 5 | G6: %
A7: Capital Adequacy | B7: ITM_120 | C7: Tier 1 Capital Ratio (%) | D7: 0 | E7: 1 | F7: 6 | G7: %
A8: Capital Adequacy | B8: ITM_TFL | C8: Fully-Loaded Tier 1 Capital Ratio (%) | D8: 0 | E8: 1 | F8: 7 | G8: %
A9: Capital Adequacy | B9: ITM_121 | C9: Total Capital Ratio (%) | D9: 0 | E9: 1 | F9: 8 | G9: %
A10: Capital Adequacy | B10: ITM_TOTFL | C10: Fully-Loaded Total Capital Ratio (%) | D10: 0 | E10: 1 | F10: 9 | G10: %
A11: Capital Adequacy | B11: ITM_OWNF | C11: Decomposition of Own Funds (%) | D11: 0 | E11: 0 | F11: 10 | G11: %
A12: Capital Adequacy | B12: ITM_130 | C12: Leverage Ratio (%) | D12: 0 | E12: 1 | F12: 11 | G12: %
A13: Profitability | B13: ITM_46 | C13: Net Interest Income to Total Operating Income (%) | D13: 0 | E13: 1 | F13: 1 | G13: %
... A55: Liquidity | B55: ITM_DTE | C55: Debt to Equity Ratio (%) | D55: 0 | E55: 1 | F55: 6 | G55: %
